<?xml version="1.0"?>
<robot name="my_robot">
 <material name="blue">
  <color rgba="0 0 0.5 1" />
 </material>
 <material name="gray">
  <color rgba="0.5 0.5 0.5 1" />
 </material> 
 <link name="base_link">
   <visual>
      <geometry>
       <box size="0.6 0.4 0.2"/>

      </geometry> 
     <origin xyz= "0 0 0.1" rpy="0 0 0" />
     <material name="blue" />
   </visual>
 </link>

 <link name="right_wheel">
    <visual>
      <geometry>
       <cylinder radius="0.1" length="0.05"/>
      </geometry>     
      <origin xyz="0.0 0.0 0.0" rpy="1.57 0.0 0.0"/>
      <material name="gray" />
    </visual>
 </link>    

 <link name="castor_wheel">
  <visual>
   <geometry>
     <sphere radius="0.05"/>
   </geometry>
   <origin xyz="0.0 0.0 0.0" rpy="0.0 0.0 0.0"/>
   <material name="gray"/>
   
  
  </visual>
 </link>


 <joint name="base_rightwheel" type="continuous">
   <parent link="base_link"/>
   <child link="right_wheel"/>
   <origin xyz="-0.15 -0.225 0.0" rpy="0.0 0.0 0.0"/>
   <axis xyz="0.0 1.0 0.0"/>
 </joint>

  <joint name="base_castor" type="fixed">
   <parent link="base_link"/>
   <child link="castor_wheel"/>
   <origin xyz="0.2 0 -0.05" rpy="0.0 0.0 0.0"/>
   <axis xyz="0.0 1.0 0.0"/>
 </joint>

   
   
    
 
       








 <!-- <link name="second_link">
  <visual>
   <geometry>
     <cylinder radius="1" length="0.2"/>
   </geometry>
   <origin xyz="0 0 0.05" rpy="0 0 0" />
   <material name= "blue" />
  </visual>
 </link>
 <link name="third_link">
  <visual>
   <geometry>
     <box size="0.1 0.1 0.1"/>
   </geometry>
   <origin xyz="0 0 0.1" rpy="0 0 0" />
   <material name= "blue" />
  </visual>
 </link>

 <joint name="base_second" type="revolute">
   <parent link="base_link"/>
   <child link="second_link"/>
   <origin xyz="0 0 0.2" rpy="0 0 0" />
   <axis xyz="0.0  0.0 1.0"/>
   <limit lower="-1.57" upper="1.57" effort="100" velocity="100"/>
   
   
  </joint >

  <joint name="second_third" type="fixed">
   <parent link="second_link"/>
   <child link="third_link"/>
   <origin xyz="0 0 0.2" rpy="0 0 0" />   -->
   
    


</robot>  


 